Traceback (most recent call last):
  File "/Users/Karen/opt/anaconda3/lib/python3.8/site-packages/jupyter_cache/executors/utils.py", line 51, in single_nb_execution
    executenb(
  File "/Users/Karen/opt/anaconda3/lib/python3.8/site-packages/nbclient/client.py", line 1082, in execute
    return NotebookClient(nb=nb, resources=resources, km=km, **kwargs).execute()
  File "/Users/Karen/opt/anaconda3/lib/python3.8/site-packages/nbclient/util.py", line 74, in wrapped
    return just_run(coro(*args, **kwargs))
  File "/Users/Karen/opt/anaconda3/lib/python3.8/site-packages/nbclient/util.py", line 53, in just_run
    return loop.run_until_complete(coro)
  File "/Users/Karen/opt/anaconda3/lib/python3.8/asyncio/base_events.py", line 616, in run_until_complete
    return future.result()
  File "/Users/Karen/opt/anaconda3/lib/python3.8/site-packages/nbclient/client.py", line 535, in async_execute
    await self.async_execute_cell(
  File "/Users/Karen/opt/anaconda3/lib/python3.8/site-packages/nbclient/client.py", line 827, in async_execute_cell
    self._check_raise_for_error(cell, exec_reply)
  File "/Users/Karen/opt/anaconda3/lib/python3.8/site-packages/nbclient/client.py", line 735, in _check_raise_for_error
    raise CellExecutionError.from_cell_and_msg(cell, exec_reply['content'])
nbclient.exceptions.CellExecutionError: An error occurred while executing the following cell:
------------------
# plotting parameters
FS = 14
inc = -1
mult_fac = 15

# plot columns of A on 2-D plane
plt.figure(figsize=(12,12))
plt.plot(A[0],A[1], marker = 'o', linestyle = '', markersize = 10, color = 'r',markeredgecolor = 'lightgray')

# label each point
txt_str = r"($" + str(A[0][0]) + r"$, $" + str(A[0][1]) + r"$)"
plt.text(A[0][0]-inc, A[1][0], txt_str, color = 'black', 
         fontsize = FS, horizontalalignment = 'right',verticalalignment = 'bottom')

txt_str = r"($" + str(A[1][0]) + r"$, $" + str(A[1][1]) + r"$)"
plt.text(A[0][1]+inc, A[1][1], txt_str, color = 'black',
         fontsize = FS, horizontalalignment = 'left',verticalalignment = 'bottom')

plt.axvline(0,linewidth = 2)
plt.axhline(0,linewidth = 2)

plt.plot([E[0,0]*-mult_fact, E[0,0]*mult_fact],[E[-1,0]*-mult_fact, E[-1,0]*mult_fact],linestyle = '--', linewidth = 2, color = 'k')

plt.xlim(-4, 4)
plt.ylim(-4, 4)

plt.xlabel('x')
plt.ylabel('y') 

plt.show()
------------------

[0;31m---------------------------------------------------------------------------[0m
[0;31mNameError[0m                                 Traceback (most recent call last)
[0;32m<ipython-input-8-1e8c20724e33>[0m in [0;36m<module>[0;34m[0m
[1;32m     20[0m [0mplt[0m[0;34m.[0m[0maxhline[0m[0;34m([0m[0;36m0[0m[0;34m,[0m[0mlinewidth[0m [0;34m=[0m [0;36m2[0m[0;34m)[0m[0;34m[0m[0;34m[0m[0m
[1;32m     21[0m [0;34m[0m[0m
[0;32m---> 22[0;31m [0mplt[0m[0;34m.[0m[0mplot[0m[0;34m([0m[0;34m[[0m[0mE[0m[0;34m[[0m[0;36m0[0m[0;34m,[0m[0;36m0[0m[0;34m][0m[0;34m*[0m[0;34m-[0m[0mmult_fact[0m[0;34m,[0m [0mE[0m[0;34m[[0m[0;36m0[0m[0;34m,[0m[0;36m0[0m[0;34m][0m[0;34m*[0m[0mmult_fact[0m[0;34m][0m[0;34m,[0m[0;34m[[0m[0mE[0m[0;34m[[0m[0;34m-[0m[0;36m1[0m[0;34m,[0m[0;36m0[0m[0;34m][0m[0;34m*[0m[0;34m-[0m[0mmult_fact[0m[0;34m,[0m [0mE[0m[0;34m[[0m[0;34m-[0m[0;36m1[0m[0;34m,[0m[0;36m0[0m[0;34m][0m[0;34m*[0m[0mmult_fact[0m[0;34m][0m[0;34m,[0m[0mlinestyle[0m [0;34m=[0m [0;34m'--'[0m[0;34m,[0m [0mlinewidth[0m [0;34m=[0m [0;36m2[0m[0;34m,[0m [0mcolor[0m [0;34m=[0m [0;34m'k'[0m[0;34m)[0m[0;34m[0m[0;34m[0m[0m
[0m[1;32m     23[0m [0;34m[0m[0m
[1;32m     24[0m [0mplt[0m[0;34m.[0m[0mxlim[0m[0;34m([0m[0;34m-[0m[0;36m4[0m[0;34m,[0m [0;36m4[0m[0;34m)[0m[0;34m[0m[0;34m[0m[0m

[0;31mNameError[0m: name 'mult_fact' is not defined
NameError: name 'mult_fact' is not defined

