Traceback (most recent call last):
  File "/Users/Karen/opt/anaconda3/lib/python3.8/site-packages/jupyter_cache/executors/utils.py", line 51, in single_nb_execution
    executenb(
  File "/Users/Karen/opt/anaconda3/lib/python3.8/site-packages/nbclient/client.py", line 1082, in execute
    return NotebookClient(nb=nb, resources=resources, km=km, **kwargs).execute()
  File "/Users/Karen/opt/anaconda3/lib/python3.8/site-packages/nbclient/util.py", line 74, in wrapped
    return just_run(coro(*args, **kwargs))
  File "/Users/Karen/opt/anaconda3/lib/python3.8/site-packages/nbclient/util.py", line 53, in just_run
    return loop.run_until_complete(coro)
  File "/Users/Karen/opt/anaconda3/lib/python3.8/asyncio/base_events.py", line 616, in run_until_complete
    return future.result()
  File "/Users/Karen/opt/anaconda3/lib/python3.8/site-packages/nbclient/client.py", line 535, in async_execute
    await self.async_execute_cell(
  File "/Users/Karen/opt/anaconda3/lib/python3.8/site-packages/nbclient/client.py", line 827, in async_execute_cell
    self._check_raise_for_error(cell, exec_reply)
  File "/Users/Karen/opt/anaconda3/lib/python3.8/site-packages/nbclient/client.py", line 735, in _check_raise_for_error
    raise CellExecutionError.from_cell_and_msg(cell, exec_reply['content'])
nbclient.exceptions.CellExecutionError: An error occurred while executing the following cell:
------------------
nc = Dataset('ERSST_v5_data.nc')
sst = nc.variables['sst'][:]
lat = nc.variables['Y'][:]
lon = nc.variables['X'][:]
time = nc.variables['T'][:]
------------------

[0;31m---------------------------------------------------------------------------[0m
[0;31mFileNotFoundError[0m                         Traceback (most recent call last)
[0;32m<ipython-input-2-5748499526f9>[0m in [0;36m<module>[0;34m[0m
[0;32m----> 1[0;31m [0mnc[0m [0;34m=[0m [0mDataset[0m[0;34m([0m[0;34m'ERSST_v5_data.nc'[0m[0;34m)[0m[0;34m[0m[0;34m[0m[0m
[0m[1;32m      2[0m [0msst[0m [0;34m=[0m [0mnc[0m[0;34m.[0m[0mvariables[0m[0;34m[[0m[0;34m'sst'[0m[0;34m][0m[0;34m[[0m[0;34m:[0m[0;34m][0m[0;34m[0m[0;34m[0m[0m
[1;32m      3[0m [0mlat[0m [0;34m=[0m [0mnc[0m[0;34m.[0m[0mvariables[0m[0;34m[[0m[0;34m'Y'[0m[0;34m][0m[0;34m[[0m[0;34m:[0m[0;34m][0m[0;34m[0m[0;34m[0m[0m
[1;32m      4[0m [0mlon[0m [0;34m=[0m [0mnc[0m[0;34m.[0m[0mvariables[0m[0;34m[[0m[0;34m'X'[0m[0;34m][0m[0;34m[[0m[0;34m:[0m[0;34m][0m[0;34m[0m[0;34m[0m[0m
[1;32m      5[0m [0mtime[0m [0;34m=[0m [0mnc[0m[0;34m.[0m[0mvariables[0m[0;34m[[0m[0;34m'T'[0m[0;34m][0m[0;34m[[0m[0;34m:[0m[0;34m][0m[0;34m[0m[0;34m[0m[0m

[0;32mnetCDF4/_netCDF4.pyx[0m in [0;36mnetCDF4._netCDF4.Dataset.__init__[0;34m()[0m

[0;32mnetCDF4/_netCDF4.pyx[0m in [0;36mnetCDF4._netCDF4._ensure_nc_success[0;34m()[0m

[0;31mFileNotFoundError[0m: [Errno 2] No such file or directory: b'ERSST_v5_data.nc'
FileNotFoundError: [Errno 2] No such file or directory: b'ERSST_v5_data.nc'

