Traceback (most recent call last):
  File "/opt/anaconda3/envs/ccia/lib/python3.10/site-packages/nbclient/client.py", line 776, in _async_poll_for_reply
    msg = await ensure_async(self.kc.shell_channel.get_msg(timeout=new_timeout))
  File "/opt/anaconda3/envs/ccia/lib/python3.10/site-packages/jupyter_core/utils/__init__.py", line 184, in ensure_async
    result = await obj
  File "/opt/anaconda3/envs/ccia/lib/python3.10/site-packages/jupyter_client/channels.py", line 230, in get_msg
    raise Empty
_queue.Empty

During handling of the above exception, another exception occurred:

Traceback (most recent call last):
  File "/opt/anaconda3/envs/ccia/lib/python3.10/site-packages/jupyter_cache/executors/utils.py", line 58, in single_nb_execution
    executenb(
  File "/opt/anaconda3/envs/ccia/lib/python3.10/site-packages/nbclient/client.py", line 1265, in execute
    return NotebookClient(nb=nb, resources=resources, km=km, **kwargs).execute()
  File "/opt/anaconda3/envs/ccia/lib/python3.10/site-packages/jupyter_core/utils/__init__.py", line 168, in wrapped
    return loop.run_until_complete(inner)
  File "/opt/anaconda3/envs/ccia/lib/python3.10/asyncio/base_events.py", line 649, in run_until_complete
    return future.result()
  File "/opt/anaconda3/envs/ccia/lib/python3.10/site-packages/nbclient/client.py", line 703, in async_execute
    await self.async_execute_cell(
  File "/opt/anaconda3/envs/ccia/lib/python3.10/site-packages/nbclient/client.py", line 1002, in async_execute_cell
    exec_reply = await self.task_poll_for_reply
  File "/opt/anaconda3/envs/ccia/lib/python3.10/site-packages/nbclient/client.py", line 800, in _async_poll_for_reply
    error_on_timeout_execute_reply = await self._async_handle_timeout(timeout, cell)
  File "/opt/anaconda3/envs/ccia/lib/python3.10/site-packages/nbclient/client.py", line 852, in _async_handle_timeout
    raise CellTimeoutError.error_from_timeout_and_cell(
nbclient.exceptions.CellTimeoutError: A cell timed out while it was being executed, after 30 seconds.
The message was: Cell execution timed out.
Here is a preview of the cell contents:
-------------------
['# the data we will use is described here', '# http://www.ncdc.noaa.gov/data-access/marineocean-data/extended-reconstructed-sea-surface-temperature-ersst-v5', '# It is stored in the IRI data library', 'iri_url = "http://iridl.ldeo.columbia.edu/SOURCES/.NOAA/.NCDC/.ERSST/.version5/.sst/"', 'T_convert = "T/[(days)(since)(1960-01-01)]sconcat/streamgridunitconvert/"']
...
['nc = Dataset(url)', "sst = nc.variables['sst'][:]", "lat = nc.variables['Y'][:]", "lon = nc.variables['X'][:]", "time = nc.variables['T'][:]"]
-------------------

